2025-03-08 21:20:32,451 INFO    Thread-98 (_run_job):40720 [wandb_setup.py:_flush():67] Current SDK version is 0.19.7
2025-03-08 21:20:32,453 INFO    Thread-98 (_run_job):40720 [wandb_setup.py:_flush():67] Configure stats pid to 40720
2025-03-08 21:20:32,454 INFO    Thread-98 (_run_job):40720 [wandb_setup.py:_flush():67] Loading settings from C:\Users\skrit\.config\wandb\settings
2025-03-08 21:20:32,456 INFO    Thread-98 (_run_job):40720 [wandb_setup.py:_flush():67] Loading settings from C:\Users\skrit\Documents\IntroDL\DA6401_Assgn1\wandb\settings
2025-03-08 21:20:32,457 INFO    Thread-98 (_run_job):40720 [wandb_setup.py:_flush():67] Loading settings from environment variables
2025-03-08 21:20:32,459 INFO    Thread-98 (_run_job):40720 [wandb_init.py:setup_run_log_directory():647] Logging user logs to C:\Users\skrit\Documents\IntroDL\DA6401_Assgn1\wandb\run-20250308_212032-lt6aj9ex\logs\debug.log
2025-03-08 21:20:32,460 INFO    Thread-98 (_run_job):40720 [wandb_init.py:setup_run_log_directory():648] Logging internal logs to C:\Users\skrit\Documents\IntroDL\DA6401_Assgn1\wandb\run-20250308_212032-lt6aj9ex\logs\debug-internal.log
2025-03-08 21:20:32,462 INFO    Thread-98 (_run_job):40720 [wandb_init.py:init():761] calling init triggers
2025-03-08 21:20:32,463 INFO    Thread-98 (_run_job):40720 [wandb_init.py:init():766] wandb.init called with sweep_config: {'activation': 'ReLU', 'batch_size': 64, 'epochs': 10, 'hidden_size': 128, 'learning_rate': 0.001, 'loss': 'mean_squared_error', 'num_layers': 5, 'optimizer': 'nadam', 'weight_decay': 0.0005, 'weight_init': 'Xavier'}
config: {'wandb_project': 'DA6401_Assignment1', 'wandb_entity': 'ns25z040-indian-institute-of-technology-madras', 'dataset': 'fashion_mnist', 'epochs': 10, 'batch_size': 32, 'loss': 'cross_entropy', 'optimizer': 'adam', 'learning_rate': 0.001, 'momentum': 0.5, 'beta': 0.5, 'beta1': 0.5, 'beta2': 0.5, 'epsilon': 1e-06, 'weight_decay': 0.0, 'weight_init': 'Xavier', 'num_layers': 3, 'hidden_size': 64, 'activation': 'ReLU', '_wandb': {}}
2025-03-08 21:20:32,464 INFO    Thread-98 (_run_job):40720 [wandb_init.py:init():784] starting backend
2025-03-08 21:20:32,465 INFO    Thread-98 (_run_job):40720 [wandb_init.py:init():788] sending inform_init request
2025-03-08 21:20:32,469 INFO    Thread-98 (_run_job):40720 [backend.py:_multiprocessing_setup():97] multiprocessing start_methods=spawn, using: spawn
2025-03-08 21:20:32,475 INFO    Thread-98 (_run_job):40720 [wandb_init.py:init():803] backend started and connected
2025-03-08 21:20:32,480 INFO    Thread-98 (_run_job):40720 [wandb_run.py:_config_callback():1261] config_cb None None {'activation': 'ReLU', 'batch_size': 64, 'epochs': 10, 'hidden_size': 128, 'learning_rate': 0.001, 'loss': 'mean_squared_error', 'num_layers': 5, 'optimizer': 'nadam', 'weight_decay': 0.0005, 'weight_init': 'Xavier'}
2025-03-08 21:20:32,482 INFO    Thread-98 (_run_job):40720 [wandb_init.py:init():896] updated telemetry
2025-03-08 21:20:32,565 INFO    Thread-98 (_run_job):40720 [wandb_init.py:init():920] communicating run to backend with 90.0 second timeout
2025-03-08 21:20:34,217 INFO    Thread-98 (_run_job):40720 [wandb_init.py:init():995] starting run threads in backend
2025-03-08 21:20:34,479 INFO    Thread-98 (_run_job):40720 [wandb_run.py:_console_start():2377] atexit reg
2025-03-08 21:20:34,480 INFO    Thread-98 (_run_job):40720 [wandb_run.py:_redirect():2227] redirect: wrap_raw
2025-03-08 21:20:34,480 INFO    Thread-98 (_run_job):40720 [wandb_run.py:_redirect():2292] Wrapping output streams.
2025-03-08 21:20:34,481 INFO    Thread-98 (_run_job):40720 [wandb_run.py:_redirect():2317] Redirects installed.
2025-03-08 21:20:34,483 INFO    Thread-98 (_run_job):40720 [wandb_init.py:init():1037] run started, returning control to user process
2025-03-08 21:23:21,117 INFO    Thread-7 (_heartbeat):40720 [retry.py:__call__():175] Retry attempt failed:
Traceback (most recent call last):
  File "C:\Users\skrit\miniconda3\envs\medllm\Lib\site-packages\urllib3\connection.py", line 196, in _new_conn
    sock = connection.create_connection(
           ^^^^^^^^^^^^^^^^^^^^^^^^^^^^^
  File "C:\Users\skrit\miniconda3\envs\medllm\Lib\site-packages\urllib3\util\connection.py", line 60, in create_connection
    for res in socket.getaddrinfo(host, port, family, socket.SOCK_STREAM):
               ^^^^^^^^^^^^^^^^^^^^^^^^^^^^^^^^^^^^^^^^^^^^^^^^^^^^^^^^^^
  File "C:\Users\skrit\miniconda3\envs\medllm\Lib\socket.py", line 976, in getaddrinfo
    for res in _socket.getaddrinfo(host, port, family, type, proto, flags):
               ^^^^^^^^^^^^^^^^^^^^^^^^^^^^^^^^^^^^^^^^^^^^^^^^^^^^^^^^^^^
socket.gaierror: [Errno 11001] getaddrinfo failed

The above exception was the direct cause of the following exception:

Traceback (most recent call last):
  File "C:\Users\skrit\miniconda3\envs\medllm\Lib\site-packages\urllib3\connectionpool.py", line 789, in urlopen
    response = self._make_request(
               ^^^^^^^^^^^^^^^^^^^
  File "C:\Users\skrit\miniconda3\envs\medllm\Lib\site-packages\urllib3\connectionpool.py", line 490, in _make_request
    raise new_e
  File "C:\Users\skrit\miniconda3\envs\medllm\Lib\site-packages\urllib3\connectionpool.py", line 466, in _make_request
    self._validate_conn(conn)
  File "C:\Users\skrit\miniconda3\envs\medllm\Lib\site-packages\urllib3\connectionpool.py", line 1095, in _validate_conn
    conn.connect()
  File "C:\Users\skrit\miniconda3\envs\medllm\Lib\site-packages\urllib3\connection.py", line 615, in connect
    self.sock = sock = self._new_conn()
                       ^^^^^^^^^^^^^^^^
  File "C:\Users\skrit\miniconda3\envs\medllm\Lib\site-packages\urllib3\connection.py", line 203, in _new_conn
    raise NameResolutionError(self.host, self, e) from e
urllib3.exceptions.NameResolutionError: <urllib3.connection.HTTPSConnection object at 0x0000024379564980>: Failed to resolve 'api.wandb.ai' ([Errno 11001] getaddrinfo failed)

The above exception was the direct cause of the following exception:

Traceback (most recent call last):
  File "C:\Users\skrit\miniconda3\envs\medllm\Lib\site-packages\requests\adapters.py", line 667, in send
    resp = conn.urlopen(
           ^^^^^^^^^^^^^
  File "C:\Users\skrit\miniconda3\envs\medllm\Lib\site-packages\urllib3\connectionpool.py", line 843, in urlopen
    retries = retries.increment(
              ^^^^^^^^^^^^^^^^^^
  File "C:\Users\skrit\miniconda3\envs\medllm\Lib\site-packages\urllib3\util\retry.py", line 519, in increment
    raise MaxRetryError(_pool, url, reason) from reason  # type: ignore[arg-type]
    ^^^^^^^^^^^^^^^^^^^^^^^^^^^^^^^^^^^^^^^^^^^^^^^^^^^
urllib3.exceptions.MaxRetryError: HTTPSConnectionPool(host='api.wandb.ai', port=443): Max retries exceeded with url: /graphql (Caused by NameResolutionError("<urllib3.connection.HTTPSConnection object at 0x0000024379564980>: Failed to resolve 'api.wandb.ai' ([Errno 11001] getaddrinfo failed)"))

During handling of the above exception, another exception occurred:

Traceback (most recent call last):
  File "C:\Users\skrit\miniconda3\envs\medllm\Lib\site-packages\wandb\sdk\lib\retry.py", line 134, in __call__
    result = self._call_fn(*args, **kwargs)
             ^^^^^^^^^^^^^^^^^^^^^^^^^^^^^^
  File "C:\Users\skrit\miniconda3\envs\medllm\Lib\site-packages\wandb\sdk\internal\internal_api.py", line 398, in execute
    return self.client.execute(*args, **kwargs)  # type: ignore
           ^^^^^^^^^^^^^^^^^^^^^^^^^^^^^^^^^^^^
  File "C:\Users\skrit\miniconda3\envs\medllm\Lib\site-packages\wandb\vendor\gql-0.2.0\wandb_gql\client.py", line 52, in execute
    result = self._get_result(document, *args, **kwargs)
             ^^^^^^^^^^^^^^^^^^^^^^^^^^^^^^^^^^^^^^^^^^^
  File "C:\Users\skrit\miniconda3\envs\medllm\Lib\site-packages\wandb\vendor\gql-0.2.0\wandb_gql\client.py", line 60, in _get_result
    return self.transport.execute(document, *args, **kwargs)
           ^^^^^^^^^^^^^^^^^^^^^^^^^^^^^^^^^^^^^^^^^^^^^^^^^
  File "C:\Users\skrit\miniconda3\envs\medllm\Lib\site-packages\wandb\sdk\lib\gql_request.py", line 58, in execute
    request = self.session.post(self.url, **post_args)
              ^^^^^^^^^^^^^^^^^^^^^^^^^^^^^^^^^^^^^^^^
  File "C:\Users\skrit\miniconda3\envs\medllm\Lib\site-packages\requests\sessions.py", line 637, in post
    return self.request("POST", url, data=data, json=json, **kwargs)
           ^^^^^^^^^^^^^^^^^^^^^^^^^^^^^^^^^^^^^^^^^^^^^^^^^^^^^^^^^
  File "C:\Users\skrit\miniconda3\envs\medllm\Lib\site-packages\requests\sessions.py", line 589, in request
    resp = self.send(prep, **send_kwargs)
           ^^^^^^^^^^^^^^^^^^^^^^^^^^^^^^
  File "C:\Users\skrit\miniconda3\envs\medllm\Lib\site-packages\requests\sessions.py", line 703, in send
    r = adapter.send(request, **kwargs)
        ^^^^^^^^^^^^^^^^^^^^^^^^^^^^^^^
  File "C:\Users\skrit\miniconda3\envs\medllm\Lib\site-packages\requests\adapters.py", line 700, in send
    raise ConnectionError(e, request=request)
requests.exceptions.ConnectionError: HTTPSConnectionPool(host='api.wandb.ai', port=443): Max retries exceeded with url: /graphql (Caused by NameResolutionError("<urllib3.connection.HTTPSConnection object at 0x0000024379564980>: Failed to resolve 'api.wandb.ai' ([Errno 11001] getaddrinfo failed)"))
2025-03-08 21:26:03,509 INFO    Thread-98 (_run_job):40720 [wandb_init.py:setup_run_log_directory():647] Logging user logs to C:\Users\skrit\Documents\IntroDL\DA6401_Assgn1\wandb\run-20250308_212603-lt6aj9ex\logs\debug.log
2025-03-08 21:26:03,510 INFO    Thread-98 (_run_job):40720 [wandb_init.py:setup_run_log_directory():648] Logging internal logs to C:\Users\skrit\Documents\IntroDL\DA6401_Assgn1\wandb\run-20250308_212603-lt6aj9ex\logs\debug-internal.log
2025-03-08 21:26:03,511 INFO    Thread-98 (_run_job):40720 [wandb_init.py:init():761] calling init triggers
2025-03-08 21:26:03,511 INFO    Thread-98 (_run_job):40720 [wandb_init.py:init():766] wandb.init called with sweep_config: {'activation': 'ReLU', 'batch_size': 64, 'epochs': 10, 'hidden_size': 128, 'learning_rate': 0.001, 'loss': 'mean_squared_error', 'num_layers': 5, 'optimizer': 'nadam', 'weight_decay': 0.0005, 'weight_init': 'Xavier'}
config: {'_wandb': {}}
2025-03-08 21:26:03,553 INFO    Thread-98 (_run_job):40720 [wandb_init.py:init():776] wandb.init() called while a run is active
2025-03-08 21:26:03,590 INFO    Thread-98 (_run_job):40720 [wandb_run.py:_finish():2112] finishing run ns25z040-indian-institute-of-technology-madras/DA6401_Assignment1/lt6aj9ex
2025-03-08 21:26:03,592 INFO    Thread-98 (_run_job):40720 [wandb_run.py:_atexit_cleanup():2342] got exitcode: 0
2025-03-08 21:26:03,592 INFO    Thread-98 (_run_job):40720 [wandb_run.py:_restore():2324] restore
2025-03-08 21:26:03,593 INFO    Thread-98 (_run_job):40720 [wandb_run.py:_restore():2330] restore done
2025-03-08 21:26:06,547 INFO    MsgRouterThr:40720 [mailbox.py:close():115] Closing mailbox, abandoning 1 handles.
2025-03-08 21:26:06,550 INFO    Thread-98 (_run_job):40720 [wandb_run.py:_footer_history_summary_info():3958] rendering history
2025-03-08 21:26:06,553 INFO    Thread-98 (_run_job):40720 [wandb_run.py:_footer_history_summary_info():3990] rendering summary
2025-03-08 21:26:06,556 INFO    Thread-98 (_run_job):40720 [wandb_run.py:_footer_sync_info():3919] logging synced files
