2025-03-08 12:59:14,411 INFO    Thread-43 (_run_job):16592 [wandb_setup.py:_flush():67] Current SDK version is 0.19.7
2025-03-08 12:59:14,411 INFO    Thread-43 (_run_job):16592 [wandb_setup.py:_flush():67] Configure stats pid to 16592
2025-03-08 12:59:14,411 INFO    Thread-43 (_run_job):16592 [wandb_setup.py:_flush():67] Loading settings from C:\Users\skrit\.config\wandb\settings
2025-03-08 12:59:14,413 INFO    Thread-43 (_run_job):16592 [wandb_setup.py:_flush():67] Loading settings from C:\Users\skrit\Documents\IntroDL\DA6401_Assgn1\wandb\settings
2025-03-08 12:59:14,415 INFO    Thread-43 (_run_job):16592 [wandb_setup.py:_flush():67] Loading settings from environment variables
2025-03-08 12:59:14,415 INFO    Thread-43 (_run_job):16592 [wandb_init.py:setup_run_log_directory():647] Logging user logs to C:\Users\skrit\Documents\IntroDL\DA6401_Assgn1\wandb\run-20250308_125914-6vodjjg5\logs\debug.log
2025-03-08 12:59:14,417 INFO    Thread-43 (_run_job):16592 [wandb_init.py:setup_run_log_directory():648] Logging internal logs to C:\Users\skrit\Documents\IntroDL\DA6401_Assgn1\wandb\run-20250308_125914-6vodjjg5\logs\debug-internal.log
2025-03-08 12:59:14,417 INFO    Thread-43 (_run_job):16592 [wandb_init.py:init():761] calling init triggers
2025-03-08 12:59:14,417 INFO    Thread-43 (_run_job):16592 [wandb_init.py:init():766] wandb.init called with sweep_config: {'activation': 'tanh', 'batch_size': 64, 'beta1': 0.9, 'beta2': 0.999, 'epochs': 30, 'hidden_size': 256, 'learning_rate': 0.001, 'num_layers': 3, 'optimizer': 'nadam', 'weight_decay': 0, 'weight_init': 'Xavier'}
config: {'wandb_project': 'DA6401_Assignment1', 'wandb_entity': 'ns25z040-indian-institute-of-technology-madras', 'dataset': 'fashion_mnist', 'epochs': 10, 'batch_size': 32, 'loss': 'cross_entropy', 'optimizer': 'adam', 'learning_rate': 0.001, 'momentum': 0.5, 'beta': 0.5, 'beta1': 0.5, 'beta2': 0.5, 'epsilon': 1e-06, 'weight_decay': 0.0, 'weight_init': 'Xavier', 'num_layers': 3, 'hidden_size': 64, 'activation': 'ReLU', '_wandb': {}}
2025-03-08 12:59:14,417 INFO    Thread-43 (_run_job):16592 [wandb_init.py:init():784] starting backend
2025-03-08 12:59:14,417 INFO    Thread-43 (_run_job):16592 [wandb_init.py:init():788] sending inform_init request
2025-03-08 12:59:14,423 INFO    Thread-43 (_run_job):16592 [backend.py:_multiprocessing_setup():97] multiprocessing start_methods=spawn, using: spawn
2025-03-08 12:59:14,427 INFO    Thread-43 (_run_job):16592 [wandb_init.py:init():803] backend started and connected
2025-03-08 12:59:14,428 INFO    Thread-43 (_run_job):16592 [wandb_run.py:_config_callback():1261] config_cb None None {'activation': 'tanh', 'batch_size': 64, 'beta1': 0.9, 'beta2': 0.999, 'epochs': 30, 'hidden_size': 256, 'learning_rate': 0.001, 'num_layers': 3, 'optimizer': 'nadam', 'weight_decay': 0, 'weight_init': 'Xavier'}
2025-03-08 12:59:14,472 INFO    Thread-43 (_run_job):16592 [wandb_init.py:init():896] updated telemetry
2025-03-08 12:59:14,681 INFO    Thread-43 (_run_job):16592 [wandb_init.py:init():920] communicating run to backend with 90.0 second timeout
2025-03-08 12:59:15,090 INFO    Thread-43 (_run_job):16592 [wandb_init.py:init():995] starting run threads in backend
2025-03-08 12:59:16,149 INFO    Thread-43 (_run_job):16592 [wandb_run.py:_console_start():2377] atexit reg
2025-03-08 12:59:16,149 INFO    Thread-43 (_run_job):16592 [wandb_run.py:_redirect():2227] redirect: wrap_raw
2025-03-08 12:59:16,149 INFO    Thread-43 (_run_job):16592 [wandb_run.py:_redirect():2292] Wrapping output streams.
2025-03-08 12:59:16,149 INFO    Thread-43 (_run_job):16592 [wandb_run.py:_redirect():2317] Redirects installed.
2025-03-08 12:59:16,151 INFO    Thread-43 (_run_job):16592 [wandb_init.py:init():1037] run started, returning control to user process
2025-03-08 13:12:59,723 INFO    Thread-7 (_heartbeat):16592 [retry.py:__call__():175] Retry attempt failed:
Traceback (most recent call last):
  File "C:\Users\skrit\miniconda3\envs\medllm\Lib\site-packages\urllib3\connection.py", line 196, in _new_conn
    sock = connection.create_connection(
           ^^^^^^^^^^^^^^^^^^^^^^^^^^^^^
  File "C:\Users\skrit\miniconda3\envs\medllm\Lib\site-packages\urllib3\util\connection.py", line 60, in create_connection
    for res in socket.getaddrinfo(host, port, family, socket.SOCK_STREAM):
               ^^^^^^^^^^^^^^^^^^^^^^^^^^^^^^^^^^^^^^^^^^^^^^^^^^^^^^^^^^
  File "C:\Users\skrit\miniconda3\envs\medllm\Lib\socket.py", line 976, in getaddrinfo
    for res in _socket.getaddrinfo(host, port, family, type, proto, flags):
               ^^^^^^^^^^^^^^^^^^^^^^^^^^^^^^^^^^^^^^^^^^^^^^^^^^^^^^^^^^^
socket.gaierror: [Errno 11001] getaddrinfo failed

The above exception was the direct cause of the following exception:

Traceback (most recent call last):
  File "C:\Users\skrit\miniconda3\envs\medllm\Lib\site-packages\urllib3\connectionpool.py", line 789, in urlopen
    response = self._make_request(
               ^^^^^^^^^^^^^^^^^^^
  File "C:\Users\skrit\miniconda3\envs\medllm\Lib\site-packages\urllib3\connectionpool.py", line 490, in _make_request
    raise new_e
  File "C:\Users\skrit\miniconda3\envs\medllm\Lib\site-packages\urllib3\connectionpool.py", line 466, in _make_request
    self._validate_conn(conn)
  File "C:\Users\skrit\miniconda3\envs\medllm\Lib\site-packages\urllib3\connectionpool.py", line 1095, in _validate_conn
    conn.connect()
  File "C:\Users\skrit\miniconda3\envs\medllm\Lib\site-packages\urllib3\connection.py", line 615, in connect
    self.sock = sock = self._new_conn()
                       ^^^^^^^^^^^^^^^^
  File "C:\Users\skrit\miniconda3\envs\medllm\Lib\site-packages\urllib3\connection.py", line 203, in _new_conn
    raise NameResolutionError(self.host, self, e) from e
urllib3.exceptions.NameResolutionError: <urllib3.connection.HTTPSConnection object at 0x000001A40A02BF20>: Failed to resolve 'api.wandb.ai' ([Errno 11001] getaddrinfo failed)

The above exception was the direct cause of the following exception:

Traceback (most recent call last):
  File "C:\Users\skrit\miniconda3\envs\medllm\Lib\site-packages\requests\adapters.py", line 667, in send
    resp = conn.urlopen(
           ^^^^^^^^^^^^^
  File "C:\Users\skrit\miniconda3\envs\medllm\Lib\site-packages\urllib3\connectionpool.py", line 843, in urlopen
    retries = retries.increment(
              ^^^^^^^^^^^^^^^^^^
  File "C:\Users\skrit\miniconda3\envs\medllm\Lib\site-packages\urllib3\util\retry.py", line 519, in increment
    raise MaxRetryError(_pool, url, reason) from reason  # type: ignore[arg-type]
    ^^^^^^^^^^^^^^^^^^^^^^^^^^^^^^^^^^^^^^^^^^^^^^^^^^^
urllib3.exceptions.MaxRetryError: HTTPSConnectionPool(host='api.wandb.ai', port=443): Max retries exceeded with url: /graphql (Caused by NameResolutionError("<urllib3.connection.HTTPSConnection object at 0x000001A40A02BF20>: Failed to resolve 'api.wandb.ai' ([Errno 11001] getaddrinfo failed)"))

During handling of the above exception, another exception occurred:

Traceback (most recent call last):
  File "C:\Users\skrit\miniconda3\envs\medllm\Lib\site-packages\wandb\sdk\lib\retry.py", line 134, in __call__
    result = self._call_fn(*args, **kwargs)
             ^^^^^^^^^^^^^^^^^^^^^^^^^^^^^^
  File "C:\Users\skrit\miniconda3\envs\medllm\Lib\site-packages\wandb\sdk\internal\internal_api.py", line 398, in execute
    return self.client.execute(*args, **kwargs)  # type: ignore
           ^^^^^^^^^^^^^^^^^^^^^^^^^^^^^^^^^^^^
  File "C:\Users\skrit\miniconda3\envs\medllm\Lib\site-packages\wandb\vendor\gql-0.2.0\wandb_gql\client.py", line 52, in execute
    result = self._get_result(document, *args, **kwargs)
             ^^^^^^^^^^^^^^^^^^^^^^^^^^^^^^^^^^^^^^^^^^^
  File "C:\Users\skrit\miniconda3\envs\medllm\Lib\site-packages\wandb\vendor\gql-0.2.0\wandb_gql\client.py", line 60, in _get_result
    return self.transport.execute(document, *args, **kwargs)
           ^^^^^^^^^^^^^^^^^^^^^^^^^^^^^^^^^^^^^^^^^^^^^^^^^
  File "C:\Users\skrit\miniconda3\envs\medllm\Lib\site-packages\wandb\sdk\lib\gql_request.py", line 58, in execute
    request = self.session.post(self.url, **post_args)
              ^^^^^^^^^^^^^^^^^^^^^^^^^^^^^^^^^^^^^^^^
  File "C:\Users\skrit\miniconda3\envs\medllm\Lib\site-packages\requests\sessions.py", line 637, in post
    return self.request("POST", url, data=data, json=json, **kwargs)
           ^^^^^^^^^^^^^^^^^^^^^^^^^^^^^^^^^^^^^^^^^^^^^^^^^^^^^^^^^
  File "C:\Users\skrit\miniconda3\envs\medllm\Lib\site-packages\requests\sessions.py", line 589, in request
    resp = self.send(prep, **send_kwargs)
           ^^^^^^^^^^^^^^^^^^^^^^^^^^^^^^
  File "C:\Users\skrit\miniconda3\envs\medllm\Lib\site-packages\requests\sessions.py", line 703, in send
    r = adapter.send(request, **kwargs)
        ^^^^^^^^^^^^^^^^^^^^^^^^^^^^^^^
  File "C:\Users\skrit\miniconda3\envs\medllm\Lib\site-packages\requests\adapters.py", line 700, in send
    raise ConnectionError(e, request=request)
requests.exceptions.ConnectionError: HTTPSConnectionPool(host='api.wandb.ai', port=443): Max retries exceeded with url: /graphql (Caused by NameResolutionError("<urllib3.connection.HTTPSConnection object at 0x000001A40A02BF20>: Failed to resolve 'api.wandb.ai' ([Errno 11001] getaddrinfo failed)"))
2025-03-08 13:13:59,147 INFO    Thread-7 (_heartbeat):16592 [retry.py:__call__():175] Retry attempt failed:
Traceback (most recent call last):
  File "C:\Users\skrit\miniconda3\envs\medllm\Lib\site-packages\urllib3\connection.py", line 196, in _new_conn
    sock = connection.create_connection(
           ^^^^^^^^^^^^^^^^^^^^^^^^^^^^^
  File "C:\Users\skrit\miniconda3\envs\medllm\Lib\site-packages\urllib3\util\connection.py", line 60, in create_connection
    for res in socket.getaddrinfo(host, port, family, socket.SOCK_STREAM):
               ^^^^^^^^^^^^^^^^^^^^^^^^^^^^^^^^^^^^^^^^^^^^^^^^^^^^^^^^^^
  File "C:\Users\skrit\miniconda3\envs\medllm\Lib\socket.py", line 976, in getaddrinfo
    for res in _socket.getaddrinfo(host, port, family, type, proto, flags):
               ^^^^^^^^^^^^^^^^^^^^^^^^^^^^^^^^^^^^^^^^^^^^^^^^^^^^^^^^^^^
socket.gaierror: [Errno 11001] getaddrinfo failed

The above exception was the direct cause of the following exception:

Traceback (most recent call last):
  File "C:\Users\skrit\miniconda3\envs\medllm\Lib\site-packages\urllib3\connectionpool.py", line 789, in urlopen
    response = self._make_request(
               ^^^^^^^^^^^^^^^^^^^
  File "C:\Users\skrit\miniconda3\envs\medllm\Lib\site-packages\urllib3\connectionpool.py", line 490, in _make_request
    raise new_e
  File "C:\Users\skrit\miniconda3\envs\medllm\Lib\site-packages\urllib3\connectionpool.py", line 466, in _make_request
    self._validate_conn(conn)
  File "C:\Users\skrit\miniconda3\envs\medllm\Lib\site-packages\urllib3\connectionpool.py", line 1095, in _validate_conn
    conn.connect()
  File "C:\Users\skrit\miniconda3\envs\medllm\Lib\site-packages\urllib3\connection.py", line 615, in connect
    self.sock = sock = self._new_conn()
                       ^^^^^^^^^^^^^^^^
  File "C:\Users\skrit\miniconda3\envs\medllm\Lib\site-packages\urllib3\connection.py", line 203, in _new_conn
    raise NameResolutionError(self.host, self, e) from e
urllib3.exceptions.NameResolutionError: <urllib3.connection.HTTPSConnection object at 0x000001A40D428500>: Failed to resolve 'api.wandb.ai' ([Errno 11001] getaddrinfo failed)

The above exception was the direct cause of the following exception:

Traceback (most recent call last):
  File "C:\Users\skrit\miniconda3\envs\medllm\Lib\site-packages\requests\adapters.py", line 667, in send
    resp = conn.urlopen(
           ^^^^^^^^^^^^^
  File "C:\Users\skrit\miniconda3\envs\medllm\Lib\site-packages\urllib3\connectionpool.py", line 843, in urlopen
    retries = retries.increment(
              ^^^^^^^^^^^^^^^^^^
  File "C:\Users\skrit\miniconda3\envs\medllm\Lib\site-packages\urllib3\util\retry.py", line 519, in increment
    raise MaxRetryError(_pool, url, reason) from reason  # type: ignore[arg-type]
    ^^^^^^^^^^^^^^^^^^^^^^^^^^^^^^^^^^^^^^^^^^^^^^^^^^^
urllib3.exceptions.MaxRetryError: HTTPSConnectionPool(host='api.wandb.ai', port=443): Max retries exceeded with url: /graphql (Caused by NameResolutionError("<urllib3.connection.HTTPSConnection object at 0x000001A40D428500>: Failed to resolve 'api.wandb.ai' ([Errno 11001] getaddrinfo failed)"))

During handling of the above exception, another exception occurred:

Traceback (most recent call last):
  File "C:\Users\skrit\miniconda3\envs\medllm\Lib\site-packages\wandb\sdk\lib\retry.py", line 134, in __call__
    result = self._call_fn(*args, **kwargs)
             ^^^^^^^^^^^^^^^^^^^^^^^^^^^^^^
  File "C:\Users\skrit\miniconda3\envs\medllm\Lib\site-packages\wandb\sdk\internal\internal_api.py", line 398, in execute
    return self.client.execute(*args, **kwargs)  # type: ignore
           ^^^^^^^^^^^^^^^^^^^^^^^^^^^^^^^^^^^^
  File "C:\Users\skrit\miniconda3\envs\medllm\Lib\site-packages\wandb\vendor\gql-0.2.0\wandb_gql\client.py", line 52, in execute
    result = self._get_result(document, *args, **kwargs)
             ^^^^^^^^^^^^^^^^^^^^^^^^^^^^^^^^^^^^^^^^^^^
  File "C:\Users\skrit\miniconda3\envs\medllm\Lib\site-packages\wandb\vendor\gql-0.2.0\wandb_gql\client.py", line 60, in _get_result
    return self.transport.execute(document, *args, **kwargs)
           ^^^^^^^^^^^^^^^^^^^^^^^^^^^^^^^^^^^^^^^^^^^^^^^^^
  File "C:\Users\skrit\miniconda3\envs\medllm\Lib\site-packages\wandb\sdk\lib\gql_request.py", line 58, in execute
    request = self.session.post(self.url, **post_args)
              ^^^^^^^^^^^^^^^^^^^^^^^^^^^^^^^^^^^^^^^^
  File "C:\Users\skrit\miniconda3\envs\medllm\Lib\site-packages\requests\sessions.py", line 637, in post
    return self.request("POST", url, data=data, json=json, **kwargs)
           ^^^^^^^^^^^^^^^^^^^^^^^^^^^^^^^^^^^^^^^^^^^^^^^^^^^^^^^^^
  File "C:\Users\skrit\miniconda3\envs\medllm\Lib\site-packages\requests\sessions.py", line 589, in request
    resp = self.send(prep, **send_kwargs)
           ^^^^^^^^^^^^^^^^^^^^^^^^^^^^^^
  File "C:\Users\skrit\miniconda3\envs\medllm\Lib\site-packages\requests\sessions.py", line 703, in send
    r = adapter.send(request, **kwargs)
        ^^^^^^^^^^^^^^^^^^^^^^^^^^^^^^^
  File "C:\Users\skrit\miniconda3\envs\medllm\Lib\site-packages\requests\adapters.py", line 700, in send
    raise ConnectionError(e, request=request)
requests.exceptions.ConnectionError: HTTPSConnectionPool(host='api.wandb.ai', port=443): Max retries exceeded with url: /graphql (Caused by NameResolutionError("<urllib3.connection.HTTPSConnection object at 0x000001A40D428500>: Failed to resolve 'api.wandb.ai' ([Errno 11001] getaddrinfo failed)"))
2025-03-08 13:14:34,735 INFO    Thread-43 (_run_job):16592 [wandb_run.py:_finish():2112] finishing run ns25z040-indian-institute-of-technology-madras/DA6401_Assignment1/6vodjjg5
2025-03-08 13:14:34,736 INFO    Thread-43 (_run_job):16592 [wandb_run.py:_atexit_cleanup():2342] got exitcode: 0
2025-03-08 13:14:34,738 INFO    Thread-43 (_run_job):16592 [wandb_run.py:_restore():2324] restore
2025-03-08 13:14:34,739 INFO    Thread-43 (_run_job):16592 [wandb_run.py:_restore():2330] restore done
2025-03-08 13:15:35,556 INFO    MsgRouterThr:16592 [mailbox.py:close():115] Closing mailbox, abandoning 1 handles.
2025-03-08 13:15:35,558 INFO    Thread-43 (_run_job):16592 [wandb_run.py:_footer_history_summary_info():3958] rendering history
2025-03-08 13:15:35,559 INFO    Thread-43 (_run_job):16592 [wandb_run.py:_footer_history_summary_info():3990] rendering summary
2025-03-08 13:15:35,560 INFO    Thread-43 (_run_job):16592 [wandb_run.py:_footer_sync_info():3919] logging synced files
