2025-03-07 21:07:46 ERROR 400 response executing GraphQL.
2025-03-07 21:07:46 ERROR {"errors":[{"message":"name required for project query","path":["project"]}],"data":{"project":null}}
2025-03-07 21:07:46 ERROR Traceback (most recent call last):
  File "C:\Users\skrit\miniconda3\envs\medllm\Lib\site-packages\wandb\apis\normalize.py", line 25, in wrapper
    return func(*args, **kwargs)
           ^^^^^^^^^^^^^^^^^^^^^
  File "C:\Users\skrit\miniconda3\envs\medllm\Lib\site-packages\wandb\sdk\internal\internal_api.py", line 1129, in sweep
    response = self.gql(
               ^^^^^^^^^
  File "C:\Users\skrit\miniconda3\envs\medllm\Lib\site-packages\wandb\sdk\internal\internal_api.py", line 370, in gql
    ret = self._retry_gql(
          ^^^^^^^^^^^^^^^^
  File "C:\Users\skrit\miniconda3\envs\medllm\Lib\site-packages\wandb\sdk\lib\retry.py", line 134, in __call__
    result = self._call_fn(*args, **kwargs)
             ^^^^^^^^^^^^^^^^^^^^^^^^^^^^^^
  File "C:\Users\skrit\miniconda3\envs\medllm\Lib\site-packages\wandb\sdk\internal\internal_api.py", line 398, in execute
    return self.client.execute(*args, **kwargs)  # type: ignore
           ^^^^^^^^^^^^^^^^^^^^^^^^^^^^^^^^^^^^
  File "C:\Users\skrit\miniconda3\envs\medllm\Lib\site-packages\wandb\vendor\gql-0.2.0\wandb_gql\client.py", line 52, in execute
    result = self._get_result(document, *args, **kwargs)
             ^^^^^^^^^^^^^^^^^^^^^^^^^^^^^^^^^^^^^^^^^^^
  File "C:\Users\skrit\miniconda3\envs\medllm\Lib\site-packages\wandb\vendor\gql-0.2.0\wandb_gql\client.py", line 60, in _get_result
    return self.transport.execute(document, *args, **kwargs)
           ^^^^^^^^^^^^^^^^^^^^^^^^^^^^^^^^^^^^^^^^^^^^^^^^^
  File "C:\Users\skrit\miniconda3\envs\medllm\Lib\site-packages\wandb\sdk\lib\gql_request.py", line 59, in execute
    request.raise_for_status()
  File "C:\Users\skrit\miniconda3\envs\medllm\Lib\site-packages\requests\models.py", line 1024, in raise_for_status
    raise HTTPError(http_error_msg, response=self)
requests.exceptions.HTTPError: 400 Client Error: Bad Request for url: https://api.wandb.ai/graphql

During handling of the above exception, another exception occurred:

Traceback (most recent call last):
  File "C:\Users\skrit\miniconda3\envs\medllm\Lib\site-packages\wandb\cli\cli.py", line 104, in wrapper
    return func(*args, **kwargs)
           ^^^^^^^^^^^^^^^^^^^^^
  File "C:\Users\skrit\miniconda3\envs\medllm\Lib\site-packages\wandb\cli\cli.py", line 1676, in agent
    wandb_agent.agent(sweep_id, entity=entity, project=project, count=count)
  File "C:\Users\skrit\miniconda3\envs\medllm\Lib\site-packages\wandb\wandb_agent.py", line 567, in agent
    return run_agent(
           ^^^^^^^^^^
  File "C:\Users\skrit\miniconda3\envs\medllm\Lib\site-packages\wandb\wandb_agent.py", line 526, in run_agent
    agent.run()
  File "C:\Users\skrit\miniconda3\envs\medllm\Lib\site-packages\wandb\wandb_agent.py", line 193, in run
    sweep_obj = self._api.sweep(self._sweep_id, "{}")
                ^^^^^^^^^^^^^^^^^^^^^^^^^^^^^^^^^^^^^
  File "C:\Users\skrit\miniconda3\envs\medllm\Lib\site-packages\wandb\apis\internal.py", line 134, in sweep
    return self.api.sweep(*args, **kwargs)
           ^^^^^^^^^^^^^^^^^^^^^^^^^^^^^^^
  File "C:\Users\skrit\miniconda3\envs\medllm\Lib\site-packages\wandb\apis\normalize.py", line 42, in wrapper
    raise CommError(message, error)
wandb.errors.errors.CommError: HTTP 400: name required for project query

2025-03-07 21:09:33 ERROR 400 response executing GraphQL.
2025-03-07 21:09:33 ERROR {"errors":[{"message":"name required for project query","path":["project"]}],"data":{"project":null}}
2025-03-07 21:09:33 ERROR Traceback (most recent call last):
  File "C:\Users\skrit\miniconda3\envs\medllm\Lib\site-packages\wandb\apis\normalize.py", line 25, in wrapper
    return func(*args, **kwargs)
           ^^^^^^^^^^^^^^^^^^^^^
  File "C:\Users\skrit\miniconda3\envs\medllm\Lib\site-packages\wandb\sdk\internal\internal_api.py", line 1129, in sweep
    response = self.gql(
               ^^^^^^^^^
  File "C:\Users\skrit\miniconda3\envs\medllm\Lib\site-packages\wandb\sdk\internal\internal_api.py", line 370, in gql
    ret = self._retry_gql(
          ^^^^^^^^^^^^^^^^
  File "C:\Users\skrit\miniconda3\envs\medllm\Lib\site-packages\wandb\sdk\lib\retry.py", line 134, in __call__
    result = self._call_fn(*args, **kwargs)
             ^^^^^^^^^^^^^^^^^^^^^^^^^^^^^^
  File "C:\Users\skrit\miniconda3\envs\medllm\Lib\site-packages\wandb\sdk\internal\internal_api.py", line 398, in execute
    return self.client.execute(*args, **kwargs)  # type: ignore
           ^^^^^^^^^^^^^^^^^^^^^^^^^^^^^^^^^^^^
  File "C:\Users\skrit\miniconda3\envs\medllm\Lib\site-packages\wandb\vendor\gql-0.2.0\wandb_gql\client.py", line 52, in execute
    result = self._get_result(document, *args, **kwargs)
             ^^^^^^^^^^^^^^^^^^^^^^^^^^^^^^^^^^^^^^^^^^^
  File "C:\Users\skrit\miniconda3\envs\medllm\Lib\site-packages\wandb\vendor\gql-0.2.0\wandb_gql\client.py", line 60, in _get_result
    return self.transport.execute(document, *args, **kwargs)
           ^^^^^^^^^^^^^^^^^^^^^^^^^^^^^^^^^^^^^^^^^^^^^^^^^
  File "C:\Users\skrit\miniconda3\envs\medllm\Lib\site-packages\wandb\sdk\lib\gql_request.py", line 59, in execute
    request.raise_for_status()
  File "C:\Users\skrit\miniconda3\envs\medllm\Lib\site-packages\requests\models.py", line 1024, in raise_for_status
    raise HTTPError(http_error_msg, response=self)
requests.exceptions.HTTPError: 400 Client Error: Bad Request for url: https://api.wandb.ai/graphql

During handling of the above exception, another exception occurred:

Traceback (most recent call last):
  File "C:\Users\skrit\miniconda3\envs\medllm\Lib\site-packages\wandb\cli\cli.py", line 104, in wrapper
    return func(*args, **kwargs)
           ^^^^^^^^^^^^^^^^^^^^^
  File "C:\Users\skrit\miniconda3\envs\medllm\Lib\site-packages\wandb\cli\cli.py", line 1676, in agent
    wandb_agent.agent(sweep_id, entity=entity, project=project, count=count)
  File "C:\Users\skrit\miniconda3\envs\medllm\Lib\site-packages\wandb\wandb_agent.py", line 567, in agent
    return run_agent(
           ^^^^^^^^^^
  File "C:\Users\skrit\miniconda3\envs\medllm\Lib\site-packages\wandb\wandb_agent.py", line 526, in run_agent
    agent.run()
  File "C:\Users\skrit\miniconda3\envs\medllm\Lib\site-packages\wandb\wandb_agent.py", line 193, in run
    sweep_obj = self._api.sweep(self._sweep_id, "{}")
                ^^^^^^^^^^^^^^^^^^^^^^^^^^^^^^^^^^^^^
  File "C:\Users\skrit\miniconda3\envs\medllm\Lib\site-packages\wandb\apis\internal.py", line 134, in sweep
    return self.api.sweep(*args, **kwargs)
           ^^^^^^^^^^^^^^^^^^^^^^^^^^^^^^^
  File "C:\Users\skrit\miniconda3\envs\medllm\Lib\site-packages\wandb\apis\normalize.py", line 42, in wrapper
    raise CommError(message, error)
wandb.errors.errors.CommError: HTTP 400: name required for project query

2025-03-07 21:12:28 ERROR 400 response executing GraphQL.
2025-03-07 21:12:28 ERROR {"errors":[{"message":"entityName required for project query","path":["project"]}],"data":{"project":null}}
2025-03-07 21:12:28 ERROR Traceback (most recent call last):
  File "C:\Users\skrit\miniconda3\envs\medllm\Lib\site-packages\wandb\apis\normalize.py", line 25, in wrapper
    return func(*args, **kwargs)
           ^^^^^^^^^^^^^^^^^^^^^
  File "C:\Users\skrit\miniconda3\envs\medllm\Lib\site-packages\wandb\sdk\internal\internal_api.py", line 1129, in sweep
    response = self.gql(
               ^^^^^^^^^
  File "C:\Users\skrit\miniconda3\envs\medllm\Lib\site-packages\wandb\sdk\internal\internal_api.py", line 370, in gql
    ret = self._retry_gql(
          ^^^^^^^^^^^^^^^^
  File "C:\Users\skrit\miniconda3\envs\medllm\Lib\site-packages\wandb\sdk\lib\retry.py", line 134, in __call__
    result = self._call_fn(*args, **kwargs)
             ^^^^^^^^^^^^^^^^^^^^^^^^^^^^^^
  File "C:\Users\skrit\miniconda3\envs\medllm\Lib\site-packages\wandb\sdk\internal\internal_api.py", line 398, in execute
    return self.client.execute(*args, **kwargs)  # type: ignore
           ^^^^^^^^^^^^^^^^^^^^^^^^^^^^^^^^^^^^
  File "C:\Users\skrit\miniconda3\envs\medllm\Lib\site-packages\wandb\vendor\gql-0.2.0\wandb_gql\client.py", line 52, in execute
    result = self._get_result(document, *args, **kwargs)
             ^^^^^^^^^^^^^^^^^^^^^^^^^^^^^^^^^^^^^^^^^^^
  File "C:\Users\skrit\miniconda3\envs\medllm\Lib\site-packages\wandb\vendor\gql-0.2.0\wandb_gql\client.py", line 60, in _get_result
    return self.transport.execute(document, *args, **kwargs)
           ^^^^^^^^^^^^^^^^^^^^^^^^^^^^^^^^^^^^^^^^^^^^^^^^^
  File "C:\Users\skrit\miniconda3\envs\medllm\Lib\site-packages\wandb\sdk\lib\gql_request.py", line 59, in execute
    request.raise_for_status()
  File "C:\Users\skrit\miniconda3\envs\medllm\Lib\site-packages\requests\models.py", line 1024, in raise_for_status
    raise HTTPError(http_error_msg, response=self)
requests.exceptions.HTTPError: 400 Client Error: Bad Request for url: https://api.wandb.ai/graphql

During handling of the above exception, another exception occurred:

Traceback (most recent call last):
  File "C:\Users\skrit\miniconda3\envs\medllm\Lib\site-packages\wandb\cli\cli.py", line 104, in wrapper
    return func(*args, **kwargs)
           ^^^^^^^^^^^^^^^^^^^^^
  File "C:\Users\skrit\miniconda3\envs\medllm\Lib\site-packages\wandb\cli\cli.py", line 1676, in agent
    wandb_agent.agent(sweep_id, entity=entity, project=project, count=count)
  File "C:\Users\skrit\miniconda3\envs\medllm\Lib\site-packages\wandb\wandb_agent.py", line 567, in agent
    return run_agent(
           ^^^^^^^^^^
  File "C:\Users\skrit\miniconda3\envs\medllm\Lib\site-packages\wandb\wandb_agent.py", line 526, in run_agent
    agent.run()
  File "C:\Users\skrit\miniconda3\envs\medllm\Lib\site-packages\wandb\wandb_agent.py", line 193, in run
    sweep_obj = self._api.sweep(self._sweep_id, "{}")
                ^^^^^^^^^^^^^^^^^^^^^^^^^^^^^^^^^^^^^
  File "C:\Users\skrit\miniconda3\envs\medllm\Lib\site-packages\wandb\apis\internal.py", line 134, in sweep
    return self.api.sweep(*args, **kwargs)
           ^^^^^^^^^^^^^^^^^^^^^^^^^^^^^^^
  File "C:\Users\skrit\miniconda3\envs\medllm\Lib\site-packages\wandb\apis\normalize.py", line 42, in wrapper
    raise CommError(message, error)
wandb.errors.errors.CommError: HTTP 400: entityName required for project query

2025-03-07 21:13:52 INFO Running runs: []
2025-03-07 21:13:52 INFO Agent received command: run
2025-03-07 21:13:52 INFO Agent starting run with config:
	activation: ReLU
	batch_size: 64
	epochs: 10
	hidden_size: 64
	learning_rate: 0.0001
	num_layers: 5
	optimizer: nadam
	weight_decay: 0
	weight_init: Xavier
2025-03-07 21:13:52 INFO About to run command: python  --activation=ReLU --batch_size=64 --epochs=10 --hidden_size=64 --learning_rate=0.0001 --num_layers=5 --optimizer=nadam --weight_decay=0 --weight_init=Xavier
2025-03-07 21:13:57 INFO Running runs: ['4xay1109']
2025-03-07 21:13:57 INFO Cleaning up finished run: 4xay1109
2025-03-07 21:13:58 INFO Agent received command: run
2025-03-07 21:13:58 INFO Agent starting run with config:
	activation: ReLU
	batch_size: 128
	epochs: 10
	hidden_size: 128
	learning_rate: 0.0001
	num_layers: 5
	optimizer: nadam
	weight_decay: 0
	weight_init: Xavier
2025-03-07 21:13:58 INFO About to run command: python  --activation=ReLU --batch_size=128 --epochs=10 --hidden_size=128 --learning_rate=0.0001 --num_layers=5 --optimizer=nadam --weight_decay=0 --weight_init=Xavier
2025-03-07 21:14:03 INFO Running runs: ['o7eqfn15']
2025-03-07 21:14:03 INFO Cleaning up finished run: o7eqfn15
2025-03-07 21:14:04 INFO Agent received command: run
2025-03-07 21:14:04 INFO Agent starting run with config:
	activation: ReLU
	batch_size: 64
	epochs: 10
	hidden_size: 64
	learning_rate: 0.0001
	num_layers: 5
	optimizer: adam
	weight_decay: 0
	weight_init: Xavier
2025-03-07 21:14:04 INFO About to run command: python  --activation=ReLU --batch_size=64 --epochs=10 --hidden_size=64 --learning_rate=0.0001 --num_layers=5 --optimizer=adam --weight_decay=0 --weight_init=Xavier
2025-03-07 21:14:09 INFO Running runs: ['btaihjeb']
2025-03-07 21:14:09 ERROR Detected 3 failed runs in the first 60 seconds, shutting down.
2025-03-07 21:14:09 INFO To disable this check set WANDB_AGENT_DISABLE_FLAPPING=true
2025-03-07 21:19:28 ERROR 400 response executing GraphQL.
2025-03-07 21:19:28 ERROR {"errors":[{"message":"name required for project query","path":["project"]}],"data":{"project":null}}
2025-03-07 21:19:28 ERROR Traceback (most recent call last):
  File "C:\Users\skrit\miniconda3\envs\medllm\Lib\site-packages\wandb\apis\normalize.py", line 25, in wrapper
    return func(*args, **kwargs)
           ^^^^^^^^^^^^^^^^^^^^^
  File "C:\Users\skrit\miniconda3\envs\medllm\Lib\site-packages\wandb\sdk\internal\internal_api.py", line 1129, in sweep
    response = self.gql(
               ^^^^^^^^^
  File "C:\Users\skrit\miniconda3\envs\medllm\Lib\site-packages\wandb\sdk\internal\internal_api.py", line 370, in gql
    ret = self._retry_gql(
          ^^^^^^^^^^^^^^^^
  File "C:\Users\skrit\miniconda3\envs\medllm\Lib\site-packages\wandb\sdk\lib\retry.py", line 134, in __call__
    result = self._call_fn(*args, **kwargs)
             ^^^^^^^^^^^^^^^^^^^^^^^^^^^^^^
  File "C:\Users\skrit\miniconda3\envs\medllm\Lib\site-packages\wandb\sdk\internal\internal_api.py", line 398, in execute
    return self.client.execute(*args, **kwargs)  # type: ignore
           ^^^^^^^^^^^^^^^^^^^^^^^^^^^^^^^^^^^^
  File "C:\Users\skrit\miniconda3\envs\medllm\Lib\site-packages\wandb\vendor\gql-0.2.0\wandb_gql\client.py", line 52, in execute
    result = self._get_result(document, *args, **kwargs)
             ^^^^^^^^^^^^^^^^^^^^^^^^^^^^^^^^^^^^^^^^^^^
  File "C:\Users\skrit\miniconda3\envs\medllm\Lib\site-packages\wandb\vendor\gql-0.2.0\wandb_gql\client.py", line 60, in _get_result
    return self.transport.execute(document, *args, **kwargs)
           ^^^^^^^^^^^^^^^^^^^^^^^^^^^^^^^^^^^^^^^^^^^^^^^^^
  File "C:\Users\skrit\miniconda3\envs\medllm\Lib\site-packages\wandb\sdk\lib\gql_request.py", line 59, in execute
    request.raise_for_status()
  File "C:\Users\skrit\miniconda3\envs\medllm\Lib\site-packages\requests\models.py", line 1024, in raise_for_status
    raise HTTPError(http_error_msg, response=self)
requests.exceptions.HTTPError: 400 Client Error: Bad Request for url: https://api.wandb.ai/graphql

During handling of the above exception, another exception occurred:

Traceback (most recent call last):
  File "C:\Users\skrit\miniconda3\envs\medllm\Lib\site-packages\wandb\cli\cli.py", line 104, in wrapper
    return func(*args, **kwargs)
           ^^^^^^^^^^^^^^^^^^^^^
  File "C:\Users\skrit\miniconda3\envs\medllm\Lib\site-packages\wandb\cli\cli.py", line 1676, in agent
    wandb_agent.agent(sweep_id, entity=entity, project=project, count=count)
  File "C:\Users\skrit\miniconda3\envs\medllm\Lib\site-packages\wandb\wandb_agent.py", line 567, in agent
    return run_agent(
           ^^^^^^^^^^
  File "C:\Users\skrit\miniconda3\envs\medllm\Lib\site-packages\wandb\wandb_agent.py", line 526, in run_agent
    agent.run()
  File "C:\Users\skrit\miniconda3\envs\medllm\Lib\site-packages\wandb\wandb_agent.py", line 193, in run
    sweep_obj = self._api.sweep(self._sweep_id, "{}")
                ^^^^^^^^^^^^^^^^^^^^^^^^^^^^^^^^^^^^^
  File "C:\Users\skrit\miniconda3\envs\medllm\Lib\site-packages\wandb\apis\internal.py", line 134, in sweep
    return self.api.sweep(*args, **kwargs)
           ^^^^^^^^^^^^^^^^^^^^^^^^^^^^^^^
  File "C:\Users\skrit\miniconda3\envs\medllm\Lib\site-packages\wandb\apis\normalize.py", line 42, in wrapper
    raise CommError(message, error)
wandb.errors.errors.CommError: HTTP 400: name required for project query

